[2023-10-14T23:28:11.140+0000] {taskinstance.py:1157} INFO - Dependencies all met for dep_context=non-requeueable deps ti=<TaskInstance: games_details.save_data_to_csv scheduled__2023-10-13T00:00:00+00:00 [queued]>
[2023-10-14T23:28:11.146+0000] {taskinstance.py:1157} INFO - Dependencies all met for dep_context=requeueable deps ti=<TaskInstance: games_details.save_data_to_csv scheduled__2023-10-13T00:00:00+00:00 [queued]>
[2023-10-14T23:28:11.146+0000] {taskinstance.py:1359} INFO - Starting attempt 2 of 2
[2023-10-14T23:28:11.157+0000] {taskinstance.py:1380} INFO - Executing <Task(PythonOperator): save_data_to_csv> on 2023-10-13 00:00:00+00:00
[2023-10-14T23:28:11.162+0000] {standard_task_runner.py:57} INFO - Started process 1409 to run task
[2023-10-14T23:28:11.164+0000] {standard_task_runner.py:84} INFO - Running: ['***', 'tasks', 'run', 'games_details', 'save_data_to_csv', 'scheduled__2023-10-13T00:00:00+00:00', '--job-id', '388', '--raw', '--subdir', 'DAGS_FOLDER/data_pipeline.py', '--cfg-path', '/tmp/tmppqju4m36']
[2023-10-14T23:28:11.166+0000] {standard_task_runner.py:85} INFO - Job 388: Subtask save_data_to_csv
[2023-10-14T23:28:11.201+0000] {task_command.py:415} INFO - Running <TaskInstance: games_details.save_data_to_csv scheduled__2023-10-13T00:00:00+00:00 [running]> on host 73255a4feea0
[2023-10-14T23:28:11.267+0000] {taskinstance.py:1660} INFO - Exporting env vars: AIRFLOW_CTX_DAG_OWNER='***' AIRFLOW_CTX_DAG_ID='games_details' AIRFLOW_CTX_TASK_ID='save_data_to_csv' AIRFLOW_CTX_EXECUTION_DATE='2023-10-13T00:00:00+00:00' AIRFLOW_CTX_TRY_NUMBER='2' AIRFLOW_CTX_DAG_RUN_ID='scheduled__2023-10-13T00:00:00+00:00'
[2023-10-14T23:28:11.268+0000] {taskinstance.py:1935} ERROR - Task failed with exception
Traceback (most recent call last):
  File "/home/airflow/.local/lib/python3.8/site-packages/airflow/operators/python.py", line 192, in execute
    return_value = self.execute_callable()
  File "/home/airflow/.local/lib/python3.8/site-packages/airflow/operators/python.py", line 209, in execute_callable
    return self.python_callable(*self.op_args, **self.op_kwargs)
TypeError: save_data_to_csv() missing 1 required positional argument: 'column_names'
[2023-10-14T23:28:11.274+0000] {taskinstance.py:1398} INFO - Marking task as FAILED. dag_id=games_details, task_id=save_data_to_csv, execution_date=20231013T000000, start_date=20231014T232811, end_date=20231014T232811
[2023-10-14T23:28:11.286+0000] {standard_task_runner.py:104} ERROR - Failed to execute job 388 for task save_data_to_csv (save_data_to_csv() missing 1 required positional argument: 'column_names'; 1409)
[2023-10-14T23:28:11.297+0000] {local_task_job_runner.py:228} INFO - Task exited with return code 1
[2023-10-14T23:28:11.321+0000] {taskinstance.py:2776} INFO - 0 downstream tasks scheduled from follow-on schedule check
