[2023-10-16T21:14:29.972+0000] {taskinstance.py:1147} INFO - Dependencies not met for <TaskInstance: games_details.save_data_to_csv scheduled__2023-10-15T00:00:00+00:00 [None]>, dependency 'Trigger Rule' FAILED: Task's trigger rule 'all_success' requires all upstream tasks to have succeeded, but found 1 non-success(es). upstream_states=_UpstreamTIStates(success=0, skipped=0, failed=0, upstream_failed=0, removed=0, done=0, success_setup=0, skipped_setup=0), upstream_task_ids={'extract_data'}
[2023-10-16T21:14:29.974+0000] {local_task_job_runner.py:154} INFO - Task is not able to be run
[2023-10-16T21:15:01.543+0000] {taskinstance.py:1157} INFO - Dependencies all met for dep_context=non-requeueable deps ti=<TaskInstance: games_details.save_data_to_csv scheduled__2023-10-15T00:00:00+00:00 [queued]>
[2023-10-16T21:15:01.550+0000] {taskinstance.py:1157} INFO - Dependencies all met for dep_context=requeueable deps ti=<TaskInstance: games_details.save_data_to_csv scheduled__2023-10-15T00:00:00+00:00 [queued]>
[2023-10-16T21:15:01.550+0000] {taskinstance.py:1359} INFO - Starting attempt 2 of 2
[2023-10-16T21:15:01.560+0000] {taskinstance.py:1380} INFO - Executing <Task(PythonOperator): save_data_to_csv> on 2023-10-15 00:00:00+00:00
[2023-10-16T21:15:01.565+0000] {standard_task_runner.py:57} INFO - Started process 469 to run task
[2023-10-16T21:15:01.568+0000] {standard_task_runner.py:84} INFO - Running: ['***', 'tasks', 'run', 'games_details', 'save_data_to_csv', 'scheduled__2023-10-15T00:00:00+00:00', '--job-id', '428', '--raw', '--subdir', 'DAGS_FOLDER/data_pipeline.py', '--cfg-path', '/tmp/tmphr5s16jb']
[2023-10-16T21:15:01.571+0000] {standard_task_runner.py:85} INFO - Job 428: Subtask save_data_to_csv
[2023-10-16T21:15:01.603+0000] {task_command.py:415} INFO - Running <TaskInstance: games_details.save_data_to_csv scheduled__2023-10-15T00:00:00+00:00 [running]> on host fa3bcf4e4257
[2023-10-16T21:15:01.671+0000] {taskinstance.py:1660} INFO - Exporting env vars: AIRFLOW_CTX_DAG_OWNER='***' AIRFLOW_CTX_DAG_ID='games_details' AIRFLOW_CTX_TASK_ID='save_data_to_csv' AIRFLOW_CTX_EXECUTION_DATE='2023-10-15T00:00:00+00:00' AIRFLOW_CTX_TRY_NUMBER='2' AIRFLOW_CTX_DAG_RUN_ID='scheduled__2023-10-15T00:00:00+00:00'
[2023-10-16T21:15:01.672+0000] {taskinstance.py:1935} ERROR - Task failed with exception
Traceback (most recent call last):
  File "/home/airflow/.local/lib/python3.8/site-packages/airflow/operators/python.py", line 192, in execute
    return_value = self.execute_callable()
  File "/home/airflow/.local/lib/python3.8/site-packages/airflow/operators/python.py", line 209, in execute_callable
    return self.python_callable(*self.op_args, **self.op_kwargs)
TypeError: save_data_to_csv() missing 1 required positional argument: 'column_names'
[2023-10-16T21:15:01.678+0000] {taskinstance.py:1398} INFO - Marking task as FAILED. dag_id=games_details, task_id=save_data_to_csv, execution_date=20231015T000000, start_date=20231016T211501, end_date=20231016T211501
[2023-10-16T21:15:01.688+0000] {standard_task_runner.py:104} ERROR - Failed to execute job 428 for task save_data_to_csv (save_data_to_csv() missing 1 required positional argument: 'column_names'; 469)
[2023-10-16T21:15:01.699+0000] {local_task_job_runner.py:228} INFO - Task exited with return code 1
[2023-10-16T21:15:01.724+0000] {taskinstance.py:2776} INFO - 0 downstream tasks scheduled from follow-on schedule check
