[2023-10-16T23:39:26.831+0000] {taskinstance.py:1157} INFO - Dependencies all met for dep_context=non-requeueable deps ti=<TaskInstance: games_details.save_data_to_csv scheduled__2023-10-15T00:00:00+00:00 [queued]>
[2023-10-16T23:39:26.846+0000] {taskinstance.py:1157} INFO - Dependencies all met for dep_context=requeueable deps ti=<TaskInstance: games_details.save_data_to_csv scheduled__2023-10-15T00:00:00+00:00 [queued]>
[2023-10-16T23:39:26.846+0000] {taskinstance.py:1359} INFO - Starting attempt 12 of 12
[2023-10-16T23:39:26.881+0000] {taskinstance.py:1380} INFO - Executing <Task(PythonOperator): save_data_to_csv> on 2023-10-15 00:00:00+00:00
[2023-10-16T23:39:26.890+0000] {standard_task_runner.py:57} INFO - Started process 393 to run task
[2023-10-16T23:39:26.893+0000] {standard_task_runner.py:84} INFO - Running: ['***', 'tasks', 'run', 'games_details', 'save_data_to_csv', 'scheduled__2023-10-15T00:00:00+00:00', '--job-id', '464', '--raw', '--subdir', 'DAGS_FOLDER/data_pipeline.py', '--cfg-path', '/tmp/tmp02jj0zvp']
[2023-10-16T23:39:26.902+0000] {standard_task_runner.py:85} INFO - Job 464: Subtask save_data_to_csv
[2023-10-16T23:39:27.028+0000] {task_command.py:415} INFO - Running <TaskInstance: games_details.save_data_to_csv scheduled__2023-10-15T00:00:00+00:00 [running]> on host ee1b836360c8
[2023-10-16T23:39:27.574+0000] {taskinstance.py:1660} INFO - Exporting env vars: AIRFLOW_CTX_DAG_OWNER='***' AIRFLOW_CTX_DAG_ID='games_details' AIRFLOW_CTX_TASK_ID='save_data_to_csv' AIRFLOW_CTX_EXECUTION_DATE='2023-10-15T00:00:00+00:00' AIRFLOW_CTX_TRY_NUMBER='12' AIRFLOW_CTX_DAG_RUN_ID='scheduled__2023-10-15T00:00:00+00:00'
[2023-10-16T23:39:27.575+0000] {taskinstance.py:1935} ERROR - Task failed with exception
Traceback (most recent call last):
  File "/home/airflow/.local/lib/python3.8/site-packages/airflow/operators/python.py", line 192, in execute
    return_value = self.execute_callable()
  File "/home/airflow/.local/lib/python3.8/site-packages/airflow/operators/python.py", line 209, in execute_callable
    return self.python_callable(*self.op_args, **self.op_kwargs)
TypeError: save_data_to_csv() missing 1 required positional argument: 'column_names'
[2023-10-16T23:39:27.582+0000] {taskinstance.py:1398} INFO - Marking task as FAILED. dag_id=games_details, task_id=save_data_to_csv, execution_date=20231015T000000, start_date=20231016T233926, end_date=20231016T233927
[2023-10-16T23:39:27.591+0000] {standard_task_runner.py:104} ERROR - Failed to execute job 464 for task save_data_to_csv (save_data_to_csv() missing 1 required positional argument: 'column_names'; 393)
[2023-10-16T23:39:27.610+0000] {local_task_job_runner.py:228} INFO - Task exited with return code 1
[2023-10-16T23:39:27.635+0000] {taskinstance.py:2776} INFO - 0 downstream tasks scheduled from follow-on schedule check
