[2023-10-16T19:02:06.669+0000] {taskinstance.py:1157} INFO - Dependencies all met for dep_context=non-requeueable deps ti=<TaskInstance: games_details.save_data_to_csv scheduled__2023-10-15T00:00:00+00:00 [queued]>
[2023-10-16T19:02:06.676+0000] {taskinstance.py:1157} INFO - Dependencies all met for dep_context=requeueable deps ti=<TaskInstance: games_details.save_data_to_csv scheduled__2023-10-15T00:00:00+00:00 [queued]>
[2023-10-16T19:02:06.676+0000] {taskinstance.py:1359} INFO - Starting attempt 1 of 1
[2023-10-16T19:02:06.786+0000] {taskinstance.py:1380} INFO - Executing <Task(PythonOperator): save_data_to_csv> on 2023-10-15 00:00:00+00:00
[2023-10-16T19:02:06.804+0000] {standard_task_runner.py:57} INFO - Started process 420 to run task
[2023-10-16T19:02:06.815+0000] {standard_task_runner.py:84} INFO - Running: ['***', 'tasks', 'run', 'games_details', 'save_data_to_csv', 'scheduled__2023-10-15T00:00:00+00:00', '--job-id', '408', '--raw', '--subdir', 'DAGS_FOLDER/data_pipeline.py', '--cfg-path', '/tmp/tmpd2x652tn']
[2023-10-16T19:02:06.824+0000] {standard_task_runner.py:85} INFO - Job 408: Subtask save_data_to_csv
[2023-10-16T19:02:07.333+0000] {task_command.py:415} INFO - Running <TaskInstance: games_details.save_data_to_csv scheduled__2023-10-15T00:00:00+00:00 [running]> on host b39a7dd9b7e9
[2023-10-16T19:02:07.830+0000] {taskinstance.py:1660} INFO - Exporting env vars: AIRFLOW_CTX_DAG_OWNER='***' AIRFLOW_CTX_DAG_ID='games_details' AIRFLOW_CTX_TASK_ID='save_data_to_csv' AIRFLOW_CTX_EXECUTION_DATE='2023-10-15T00:00:00+00:00' AIRFLOW_CTX_TRY_NUMBER='1' AIRFLOW_CTX_DAG_RUN_ID='scheduled__2023-10-15T00:00:00+00:00'
[2023-10-16T19:02:07.835+0000] {taskinstance.py:1935} ERROR - Task failed with exception
Traceback (most recent call last):
  File "/home/airflow/.local/lib/python3.8/site-packages/airflow/operators/python.py", line 192, in execute
    return_value = self.execute_callable()
  File "/home/airflow/.local/lib/python3.8/site-packages/airflow/operators/python.py", line 209, in execute_callable
    return self.python_callable(*self.op_args, **self.op_kwargs)
TypeError: save_data_to_csv() missing 1 required positional argument: 'column_names'
[2023-10-16T19:02:07.937+0000] {taskinstance.py:1398} INFO - Marking task as FAILED. dag_id=games_details, task_id=save_data_to_csv, execution_date=20231015T000000, start_date=20231016T190206, end_date=20231016T190207
[2023-10-16T19:02:08.251+0000] {standard_task_runner.py:104} ERROR - Failed to execute job 408 for task save_data_to_csv (save_data_to_csv() missing 1 required positional argument: 'column_names'; 420)
[2023-10-16T19:02:08.269+0000] {local_task_job_runner.py:228} INFO - Task exited with return code 1
[2023-10-16T19:02:08.298+0000] {taskinstance.py:2776} INFO - 0 downstream tasks scheduled from follow-on schedule check
