[2023-10-16T23:14:44.368+0000] {taskinstance.py:1157} INFO - Dependencies all met for dep_context=non-requeueable deps ti=<TaskInstance: games_details.save_data_to_csv scheduled__2023-10-15T00:00:00+00:00 [queued]>
[2023-10-16T23:14:44.375+0000] {taskinstance.py:1157} INFO - Dependencies all met for dep_context=requeueable deps ti=<TaskInstance: games_details.save_data_to_csv scheduled__2023-10-15T00:00:00+00:00 [queued]>
[2023-10-16T23:14:44.377+0000] {taskinstance.py:1359} INFO - Starting attempt 11 of 11
[2023-10-16T23:14:44.393+0000] {taskinstance.py:1380} INFO - Executing <Task(PythonOperator): save_data_to_csv> on 2023-10-15 00:00:00+00:00
[2023-10-16T23:14:44.400+0000] {standard_task_runner.py:57} INFO - Started process 141 to run task
[2023-10-16T23:14:44.403+0000] {standard_task_runner.py:84} INFO - Running: ['***', 'tasks', 'run', 'games_details', 'save_data_to_csv', 'scheduled__2023-10-15T00:00:00+00:00', '--job-id', '460', '--raw', '--subdir', 'DAGS_FOLDER/data_pipeline.py', '--cfg-path', '/tmp/tmpqzwwgcbi']
[2023-10-16T23:14:44.406+0000] {standard_task_runner.py:85} INFO - Job 460: Subtask save_data_to_csv
[2023-10-16T23:14:44.445+0000] {task_command.py:415} INFO - Running <TaskInstance: games_details.save_data_to_csv scheduled__2023-10-15T00:00:00+00:00 [running]> on host 650849d590a5
[2023-10-16T23:14:44.629+0000] {taskinstance.py:1660} INFO - Exporting env vars: AIRFLOW_CTX_DAG_OWNER='***' AIRFLOW_CTX_DAG_ID='games_details' AIRFLOW_CTX_TASK_ID='save_data_to_csv' AIRFLOW_CTX_EXECUTION_DATE='2023-10-15T00:00:00+00:00' AIRFLOW_CTX_TRY_NUMBER='11' AIRFLOW_CTX_DAG_RUN_ID='scheduled__2023-10-15T00:00:00+00:00'
[2023-10-16T23:14:44.633+0000] {taskinstance.py:1935} ERROR - Task failed with exception
Traceback (most recent call last):
  File "/home/airflow/.local/lib/python3.8/site-packages/airflow/operators/python.py", line 192, in execute
    return_value = self.execute_callable()
  File "/home/airflow/.local/lib/python3.8/site-packages/airflow/operators/python.py", line 209, in execute_callable
    return self.python_callable(*self.op_args, **self.op_kwargs)
TypeError: save_data_to_csv() missing 1 required positional argument: 'column_names'
[2023-10-16T23:14:44.660+0000] {taskinstance.py:1398} INFO - Marking task as FAILED. dag_id=games_details, task_id=save_data_to_csv, execution_date=20231015T000000, start_date=20231016T231444, end_date=20231016T231444
[2023-10-16T23:14:44.692+0000] {standard_task_runner.py:104} ERROR - Failed to execute job 460 for task save_data_to_csv (save_data_to_csv() missing 1 required positional argument: 'column_names'; 141)
[2023-10-16T23:14:44.739+0000] {local_task_job_runner.py:228} INFO - Task exited with return code 1
[2023-10-16T23:14:44.813+0000] {taskinstance.py:2776} INFO - 0 downstream tasks scheduled from follow-on schedule check
