[2023-10-17T16:49:18.205+0000] {taskinstance.py:1157} INFO - Dependencies all met for dep_context=non-requeueable deps ti=<TaskInstance: games_details.extract_data scheduled__2023-10-16T00:00:00+00:00 [queued]>
[2023-10-17T16:49:18.211+0000] {taskinstance.py:1157} INFO - Dependencies all met for dep_context=requeueable deps ti=<TaskInstance: games_details.extract_data scheduled__2023-10-16T00:00:00+00:00 [queued]>
[2023-10-17T16:49:18.212+0000] {taskinstance.py:1359} INFO - Starting attempt 2 of 2
[2023-10-17T16:49:18.220+0000] {taskinstance.py:1380} INFO - Executing <Task(PythonOperator): extract_data> on 2023-10-16 00:00:00+00:00
[2023-10-17T16:49:18.226+0000] {standard_task_runner.py:57} INFO - Started process 3760 to run task
[2023-10-17T16:49:18.228+0000] {standard_task_runner.py:84} INFO - Running: ['***', 'tasks', 'run', 'games_details', 'extract_data', 'scheduled__2023-10-16T00:00:00+00:00', '--job-id', '497', '--raw', '--subdir', 'DAGS_FOLDER/data_pipeline.py', '--cfg-path', '/tmp/tmpvpbbfkh1']
[2023-10-17T16:49:18.231+0000] {standard_task_runner.py:85} INFO - Job 497: Subtask extract_data
[2023-10-17T16:49:18.264+0000] {task_command.py:415} INFO - Running <TaskInstance: games_details.extract_data scheduled__2023-10-16T00:00:00+00:00 [running]> on host ee1b836360c8
[2023-10-17T16:49:18.321+0000] {taskinstance.py:1660} INFO - Exporting env vars: AIRFLOW_CTX_DAG_OWNER='***' AIRFLOW_CTX_DAG_ID='games_details' AIRFLOW_CTX_TASK_ID='extract_data' AIRFLOW_CTX_EXECUTION_DATE='2023-10-16T00:00:00+00:00' AIRFLOW_CTX_TRY_NUMBER='2' AIRFLOW_CTX_DAG_RUN_ID='scheduled__2023-10-16T00:00:00+00:00'
[2023-10-17T16:49:18.322+0000] {log.py:232} WARNING - 2023-10-17 16:49:18,322 - mi_logger - INFO - Variables de entorno establecidas con exito DB_PASS
[2023-10-17T16:49:18.322+0000] {log.py:232} WARNING - 2023-10-17 16:49:18,322 - mi_logger - INFO - Variables de entorno establecidas con exito DB_PASS
[2023-10-17T16:49:18.322+0000] {configs.py:38} INFO - Variables de entorno establecidas con exito DB_PASS
[2023-10-17T16:49:18.323+0000] {log.py:232} WARNING - 2023-10-17 16:49:18,323 - mi_logger - INFO - Variables de entorno establecidas con exito DB_NAME
[2023-10-17T16:49:18.323+0000] {log.py:232} WARNING - 2023-10-17 16:49:18,323 - mi_logger - INFO - Variables de entorno establecidas con exito DB_NAME
[2023-10-17T16:49:18.323+0000] {configs.py:38} INFO - Variables de entorno establecidas con exito DB_NAME
[2023-10-17T16:49:18.323+0000] {log.py:232} WARNING - 2023-10-17 16:49:18,323 - mi_logger - INFO - Variables de entorno establecidas con exito DB_USER
[2023-10-17T16:49:18.323+0000] {log.py:232} WARNING - 2023-10-17 16:49:18,323 - mi_logger - INFO - Variables de entorno establecidas con exito DB_USER
[2023-10-17T16:49:18.323+0000] {configs.py:38} INFO - Variables de entorno establecidas con exito DB_USER
[2023-10-17T16:49:18.323+0000] {log.py:232} WARNING - 2023-10-17 16:49:18,323 - mi_logger - INFO - Variables de entorno establecidas con exito DB_HOST
[2023-10-17T16:49:18.323+0000] {log.py:232} WARNING - 2023-10-17 16:49:18,323 - mi_logger - INFO - Variables de entorno establecidas con exito DB_HOST
[2023-10-17T16:49:18.323+0000] {configs.py:38} INFO - Variables de entorno establecidas con exito DB_HOST
[2023-10-17T16:49:18.326+0000] {log.py:232} WARNING - 2023-10-17 16:49:18,326 - mi_logger - ERROR - Error al conectar a la base de datos: (2003, "Can't connect to MySQL server on '192.168.112.4' ([Errno 111] Connection refused)")
[2023-10-17T16:49:18.326+0000] {log.py:232} WARNING - 2023-10-17 16:49:18,326 - mi_logger - ERROR - Error al conectar a la base de datos: (2003, "Can't connect to MySQL server on '192.168.112.4' ([Errno 111] Connection refused)")
[2023-10-17T16:49:18.326+0000] {cloudsql_connection.py:39} ERROR - Error al conectar a la base de datos: (2003, "Can't connect to MySQL server on '192.168.112.4' ([Errno 111] Connection refused)")
[2023-10-17T16:49:18.327+0000] {log.py:232} WARNING - 2023-10-17 16:49:18,326 - mi_logger - INFO - Error al extraer datos: __enter__
[2023-10-17T16:49:18.327+0000] {log.py:232} WARNING - 2023-10-17 16:49:18,326 - mi_logger - INFO - Error al extraer datos: __enter__
[2023-10-17T16:49:18.326+0000] {extract_data.py:24} INFO - Error al extraer datos: __enter__
[2023-10-17T16:49:18.344+0000] {python.py:194} INFO - Done. Returned value was: None
[2023-10-17T16:49:18.353+0000] {taskinstance.py:1398} INFO - Marking task as SUCCESS. dag_id=games_details, task_id=extract_data, execution_date=20231016T000000, start_date=20231017T164918, end_date=20231017T164918
[2023-10-17T16:49:18.400+0000] {local_task_job_runner.py:228} INFO - Task exited with return code 0
[2023-10-17T16:49:18.429+0000] {taskinstance.py:2776} INFO - 1 downstream tasks scheduled from follow-on schedule check
